Workbook

Sheet LEIA-ME
B2: Curadoria de anotações LC-MS/MS — Vanilla planifolia (Orchidaceae)
B3: Fonte: Lista_de_componentes_29.09.xlsx (148 linhas). Gerado por pipeline.py.
B5: Etapas do pipeline
B6: 1. Carregar | C6: Aba 1_Bruto mantém os dados originais intactos.
B7: 2. Limpar | C7: Aba 2_Limpo: separa do nome a biblioteca, o ID do banco e a energia de colisão, e registra os problemas de qualidade de cada linha.
B8: 3. Padronizar | C8: Cada nome limpo é convertido em um composto canônico (dados/sinonimos.csv). Linhas repetidas do mesmo composto são marcadas como duplicatas.
B9: 4. Curar | C9: Aba 3_Curadoria: cada composto único recebe classe, categoria A–F, grupo isomérico, nível MSI, justificativa e referências (dados/base_curadoria.csv).
B10: 5. Verificar | C10: Procura os marcadores esperados da espécie e gera os alertas listados abaixo.
B11: 6. Resumir | C11: Aba 4_Resumo: contagens por categoria e classe, calculadas por fórmula. Se você mudar uma categoria na 3_Curadoria, o resumo se atualiza.
B13: Categorias de plausibilidade
B14: Categoria | C14: Significado | D14: Ação recomendada
B15: A | C15: Relatado na espécie | D15: Manter
B16: B | C16: Relatado no gênero ou em outras espécies da família | D16: Manter
B17: C | C17: Metabólito primário/ubíquo em plantas — plausível | D17: Manter
B18: D | C18: Natural e biossinteticamente possível, sem registro encontrado na família | D18: Manter com ressalva — confirmar com padrão
B19: E | C19: Improvável na família (típico de outro táxon, microrganismo ou animal) | D19: Excluir ou reavaliar
B20: F | C20: Contaminante, sintético, fármaco ou artefato analítico | D20: Excluir
B21: P | C21: PENDENTE — composto sem curadoria na base de conhecimento | D21: Curar manualmente
B23: Alertas e observações
B24: • Ausências notáveis: Vanillin, Glucovanillin, Vanillic acid, 4-Hydroxybenzaldehyde, 4-Hydroxybenzoic acid, marcadores característicos de Vanilla planifolia, não aparecem na lista. Verificar o score de corte, outra exportação ou o tecido/extrato analisado.
B25: • Há derivados de clorofila (feofórbido/feofitina), o que indica tecido verde (folha, caule ou vagem verde).
B26: • Todas as anotações vêm de similaridade espectral em biblioteca, portanto são no máximo nível 2 do MSI (Sumner et al., 2007). Nível 1 exige padrão analítico com o mesmo tempo de retenção e o mesmo MS/MS.
B27: • Recomenda-se rodar um branco de extração (solvente + vial) para confirmar os contaminantes da categoria F.
B28: • 'Sem registro encontrado' não equivale a 'ausente na família'. Antes de excluir compostos D ou E, consultar LOTUS (lotus.naturalproducts.net) e KNApSAcK.

Sheet 4_Resumo
B2: Resumo da curadoria
B4: Categoria | C4: Plausibilidade | D4: Ação recomendada | E4: Compostos únicos | F4: Linhas da lista original | G4: % dos únicos
B5: A | C5: Relatado na espécie | D5: Manter | E5: =COUNTIF('3_Curadoria'!$F$2:$F$109,B5) | F5: =SUMIF('3_Curadoria'!$F$2:$F$109,B5,'3_Curadoria'!$D$2:$D$109) | G5: =IF($E$12=0,0,E5/$E$12)
B6: B | C6: Relatado no gênero ou em outras espécies da família | D6: Manter | E6: =COUNTIF('3_Curadoria'!$F$2:$F$109,B6) | F6: =SUMIF('3_Curadoria'!$F$2:$F$109,B6,'3_Curadoria'!$D$2:$D$109) | G6: =IF($E$12=0,0,E6/$E$12)
B7: C | C7: Metabólito primário/ubíquo em plantas — plausível | D7: Manter | E7: =COUNTIF('3_Curadoria'!$F$2:$F$109,B7) | F7: =SUMIF('3_Curadoria'!$F$2:$F$109,B7,'3_Curadoria'!$D$2:$D$109) | G7: =IF($E$12=0,0,E7/$E$12)
B8: D | C8: Natural e biossinteticamente possível, sem registro encontrado na família | D8: Manter com ressalva — confirmar com padrão | E8: =COUNTIF('3_Curadoria'!$F$2:$F$109,B8) | F8: =SUMIF('3_Curadoria'!$F$2:$F$109,B8,'3_Curadoria'!$D$2:$D$109) | G8: =IF($E$12=0,0,E8/$E$12)
B9: E | C9: Improvável na família (típico de outro táxon, microrganismo ou animal) | D9: Excluir ou reavaliar | E9: =COUNTIF('3_Curadoria'!$F$2:$F$109,B9) | F9: =SUMIF('3_Curadoria'!$F$2:$F$109,B9,'3_Curadoria'!$D$2:$D$109) | G9: =IF($E$12=0,0,E9/$E$12)
B10: F | C10: Contaminante, sintético, fármaco ou artefato analítico | D10: Excluir | E10: =COUNTIF('3_Curadoria'!$F$2:$F$109,B10) | F10: =SUMIF('3_Curadoria'!$F$2:$F$109,B10,'3_Curadoria'!$D$2:$D$109) | G10: =IF($E$12=0,0,E10/$E$12)
B11: P | C11: PENDENTE — composto sem curadoria na base de conhecimento | D11: Curar manualmente | E11: =COUNTIF('3_Curadoria'!$F$2:$F$109,B11) | F11: =SUMIF('3_Curadoria'!$F$2:$F$109,B11,'3_Curadoria'!$D$2:$D$109) | G11: =IF($E$12=0,0,E11/$E$12)
B12: Total | E12: =SUM(E5:E11) | F12: =SUM(F5:F11) | G12: =SUM(G5:G11)
B14: Indicadores do ciclo de limpeza
C15: Linhas na lista original | E15: =COUNTA('1_Bruto'!A2:A149)
C16: Compostos únicos após padronização | E16: =COUNTA('3_Curadoria'!B2:B109)
C17: Linhas redundantes (duplicatas) | E17: =COUNTIF('2_Limpo'!I2:I149,"Sim")
C18: Linhas com algum problema de qualidade | E18: =COUNTIF('2_Limpo'!G2:G149,"<>—")
C19: Compostos mantidos (A + B + C) | E19: =E5+E6+E7
C20: Compostos a confirmar (D) | E20: =E8
C21: Compostos a excluir/reavaliar (E + F) | E21: =E9+E10
C22: Compostos pendentes de curadoria (P) | E22: =E11
C23: Compostos em grupos isoméricos | E23: =COUNTIF('3_Curadoria'!I2:I109,"<>—")
B25: Compostos únicos por classe química e categoria
C26: Classe química | D26: A | E26: B | F26: C | G26: D | H26: E | I26: F | J26: P | K26: Total
C27: Acetofenona | D27: =COUNTIFS('3_Curadoria'!$C$2:$C$109,$C27,'3_Curadoria'!$F$2:$F$109,"A") | E27: =COUNTIFS('3_Curadoria'!$C$2:$C$109,$C27,'3_Curadoria'!$F$2:$F$109,"B") | F27: =COUNTIFS('3_Curadoria'!$C$2:$C$109,$C27,'3_Curadoria'!$F$2:$F$109,"C") | G27: =COUNTIFS('3_Curadoria'!$C$2:$C$109,$C27,'3_Curadoria'!$F$2:$F$109,"D") | H27: =COUNTIFS('3_Curadoria'!$C$2:$C$109,$C27,'3_Curadoria'!$F$2:$F$109,"E") | I27: =COUNTIFS('3_Curadoria'!$C$2:$C$109,$C27,'3_Curadoria'!$F$2:$F$109,"F") | J27: =COUNTIFS('3_Curadoria'!$C$2:$C$109,$C27,'3_Curadoria'!$F$2:$F$109,"P") | K27: =SUM(D27:J27)
C28: Alcaloide bisbenzilisoquinolínico | D28: =COUNTIFS('3_Curadoria'!$C$2:$C$109,$C28,'3_Curadoria'!$F$2:$F$109,"A") | E28: =COUNTIFS('3_Curadoria'!$C$2:$C$109,$C28,'3_Curadoria'!$F$2:$F$109,"B") | F28: =COUNTIFS('3_Curadoria'!$C$2:$C$109,$C28,'3_Curadoria'!$F$2:$F$109,"C") | G28: =COUNTIFS('3_Curadoria'!$C$2:$C$109,$C28,'3_Curadoria'!$F$2:$F$109,"D") | H28: =COUNTIFS('3_Curadoria'!$C$2:$C$109,$C28,'3_Curadoria'!$F$2:$F$109,"E") | I28: =COUNTIFS('3_Curadoria'!$C$2:$C$109,$C28,'3_Curadoria'!$F$2:$F$109,"F") | J28: =COUNTIFS('3_Curadoria'!$C$2:$C$109,$C28,'3_Curadoria'!$F$2:$F$109,"P") | K28: =SUM(D28:J28)
C29: Alcaloide purínico | D29: =COUNTIFS('3_Curadoria'!$C$2:$C$109,$C29,'3_Curadoria'!$F$2:$F$109,"A") | E29: =COUNTIFS('3_Curadoria'!$C$2:$C$109,$C29,'3_Curadoria'!$F$2:$F$109,"B") | F29: =COUNTIFS('3_Curadoria'!$C$2:$C$109,$C29,'3_Curadoria'!$F$2:$F$109,"C") | G29: =COUNTIFS('3_Curadoria'!$C$2:$C$109,$C29,'3_Curadoria'!$F$2:$F$109,"D") | H29: =COUNTIFS('3_Curadoria'!$C$2:$C$109,$C29,'3_Curadoria'!$F$2:$F$109,"E") | I29: =COUNTIFS('3_Curadoria'!$C$2:$C$109,$C29,'3_Curadoria'!$F$2:$F$109,"F") | J29: =COUNTIFS('3_Curadoria'!$C$2:$C$109,$C29,'3_Curadoria'!$F$2:$F$109,"P") | K29: =SUM(D29:J29)
C30: Aldeído fenólico | D30: =COUNTIFS('3_Curadoria'!$C$2:$C$109,$C30,'3_Curadoria'!$F$2:$F$109,"A") | E30: =COUNTIFS('3_Curadoria'!$C$2:$C$109,$C30,'3_Curadoria'!$F$2:$F$109,"B") | F30: =COUNTIFS('3_Curadoria'!$C$2:$C$109,$C30,'3_Curadoria'!$F$2:$F$109,"C") | G30: =COUNTIFS('3_Curadoria'!$C$2:$C$109,$C30,'3_Curadoria'!$F$2:$F$109,"D") | H30: =COUNTIFS('3_Curadoria'!$C$2:$C$109,$C30,'3_Curadoria'!$F$2:$F$109,"E") | I30: =COUNTIFS('3_Curadoria'!$C$2:$C$109,$C30,'3_Curadoria'!$F$2:$F$109,"F") | J30: =COUNTIFS('3_Curadoria'!$C$2:$C$109,$C30,'3_Curadoria'!$F$2:$F$109,"P") | K30: =SUM(D30:J30)
C31: Amida de ácido graxo | D31: =COUNTIFS('3_Curadoria'!$C$2:$C$109,$C31,'3_Curadoria'!$F$2:$F$109,"A") | E31: =COUNTIFS('3_Curadoria'!$C$2:$C$109,$C31,'3_Curadoria'!$F$2:$F$109,"B") | F31: =COUNTIFS('3_Curadoria'!$C$2:$C$109,$C31,'3_Curadoria'!$F$2:$F$109,"C") | G31: =COUNTIFS('3_Curadoria'!$C$2:$C$109,$C31,'3_Curadoria'!$F$2:$F$109,"D") | H31: =COUNTIFS('3_Curadoria'!$C$2:$C$109,$C31,'3_Curadoria'!$F$2:$F$109,"E") | I31: =COUNTIFS('3_Curadoria'!$C$2:$C$109,$C31,'3_Curadoria'!$F$2:$F$109,"F") | J31: =COUNTIFS('3_Curadoria'!$C$2:$C$109,$C31,'3_Curadoria'!$F$2:$F$109,"P") | K31: =SUM(D31:J31)
C32: Amina (estabilizante de polímero) | D32: =COUNTIFS('3_Curadoria'!$C$2:$C$109,$C32,'3_Curadoria'!$F$2:$F$109,"A") | E32: =COUNTIFS('3_Curadoria'!$C$2:$C$109,$C32,'3_Curadoria'!$F$2:$F$109,"B") | F32: =COUNTIFS('3_Curadoria'!$C$2:$C$109,$C32,'3_Curadoria'!$F$2:$F$109,"C") | G32: =COUNTIFS('3_Curadoria'!$C$2:$C$109,$C32,'3_Curadoria'!$F$2:$F$109,"D") | H32: =COUNTIFS('3_Curadoria'!$C$2:$C$109,$C32,'3_Curadoria'!$F$2:$F$109,"E") | I32: =COUNTIFS('3_Curadoria'!$C$2:$C$109,$C32,'3_Curadoria'!$F$2:$F$109,"F") | J32: =COUNTIFS('3_Curadoria'!$C$2:$C$109,$C32,'3_Curadoria'!$F$2:$F$109,"P") | K32: =SUM(D32:J32)
C33: Amina aromática | D33: =COUNTIFS('3_Curadoria'!$C$2:$C$109,$C33,'3_Curadoria'!$F$2:$F$109,"A") | E33: =COUNTIFS('3_Curadoria'!$C$2:$C$109,$C33,'3_Curadoria'!$F$2:$F$109,"B") | F33: =COUNTIFS('3_Curadoria'!$C$2:$C$109,$C33,'3_Curadoria'!$F$2:$F$109,"C") | G33: =COUNTIFS('3_Curadoria'!$C$2:$C$109,$C33,'3_Curadoria'!$F$2:$F$109,"D") | H33: =COUNTIFS('3_Curadoria'!$C$2:$C$109,$C33,'3_Curadoria'!$F$2:$F$109,"E") | I33: =COUNTIFS('3_Curadoria'!$C$2:$C$109,$C33,'3_Curadoria'!$F$2:$F$109,"F") | J33: =COUNTIFS('3_Curadoria'!$C$2:$C$109,$C33,'3_Curadoria'!$F$2:$F$109,"P") | K33: =SUM(D33:J33)
C34: Amina industrial | D34: =COUNTIFS('3_Curadoria'!$C$2:$C$109,$C34,'3_Curadoria'!$F$2:$F$109,"A") | E34: =COUNTIFS('3_Curadoria'!$C$2:$C$109,$C34,'3_Curadoria'!$F$2:$F$109,"B") | F34: =COUNTIFS('3_Curadoria'!$C$2:$C$109,$C34,'3_Curadoria'!$F$2:$F$109,"C") | G34: =COUNTIFS('3_Curadoria'!$C$2:$C$109,$C34,'3_Curadoria'!$F$2:$F$109,"D") | H34: =COUNTIFS('3_Curadoria'!$C$2:$C$109,$C34,'3_Curadoria'!$F$2:$F$109,"E") | I34: =COUNTIFS('3_Curadoria'!$C$2:$C$109,$C34,'3_Curadoria'!$F$2:$F$109,"F") | J34: =COUNTIFS('3_Curadoria'!$C$2:$C$109,$C34,'3_Curadoria'!$F$2:$F$109,"P") | K34: =SUM(D34:J34)
C35: Amina policíclica | D35: =COUNTIFS('3_Curadoria'!$C$2:$C$109,$C35,'3_Curadoria'!$F$2:$F$109,"A") | E35: =COUNTIFS('3_Curadoria'!$C$2:$C$109,$C35,'3_Curadoria'!$F$2:$F$109,"B") | F35: =COUNTIFS('3_Curadoria'!$C$2:$C$109,$C35,'3_Curadoria'!$F$2:$F$109,"C") | G35: =COUNTIFS('3_Curadoria'!$C$2:$C$109,$C35,'3_Curadoria'!$F$2:$F$109,"D") | H35: =COUNTIFS('3_Curadoria'!$C$2:$C$109,$C35,'3_Curadoria'!$F$2:$F$109,"E") | I35: =COUNTIFS('3_Curadoria'!$C$2:$C$109,$C35,'3_Curadoria'!$F$2:$F$109,"F") | J35: =COUNTIFS('3_Curadoria'!$C$2:$C$109,$C35,'3_Curadoria'!$F$2:$F$109,"P") | K35: =SUM(D35:J35)
C36: Amina quaternária | D36: =COUNTIFS('3_Curadoria'!$C$2:$C$109,$C36,'3_Curadoria'!$F$2:$F$109,"A") | E36: =COUNTIFS('3_Curadoria'!$C$2:$C$109,$C36,'3_Curadoria'!$F$2:$F$109,"B") | F36: =COUNTIFS('3_Curadoria'!$C$2:$C$109,$C36,'3_Curadoria'!$F$2:$F$109,"C") | G36: =COUNTIFS('3_Curadoria'!$C$2:$C$109,$C36,'3_Curadoria'!$F$2:$F$109,"D") | H36: =COUNTIFS('3_Curadoria'!$C$2:$C$109,$C36,'3_Curadoria'!$F$2:$F$109,"E") | I36: =COUNTIFS('3_Curadoria'!$C$2:$C$109,$C36,'3_Curadoria'!$F$2:$F$109,"F") | J36: =COUNTIFS('3_Curadoria'!$C$2:$C$109,$C36,'3_Curadoria'!$F$2:$F$109,"P") | K36: =SUM(D36:J36)
C37: Aminoaçúcar | D37: =COUNTIFS('3_Curadoria'!$C$2:$C$109,$C37,'3_Curadoria'!$F$2:$F$109,"A") | E37: =COUNTIFS('3_Curadoria'!$C$2:$C$109,$C37,'3_Curadoria'!$F$2:$F$109,"B") | F37: =COUNTIFS('3_Curadoria'!$C$2:$C$109,$C37,'3_Curadoria'!$F$2:$F$109,"C") | G37: =COUNTIFS('3_Curadoria'!$C$2:$C$109,$C37,'3_Curadoria'!$F$2:$F$109,"D") | H37: =COUNTIFS('3_Curadoria'!$C$2:$C$109,$C37,'3_Curadoria'!$F$2:$F$109,"E") | I37: =COUNTIFS('3_Curadoria'!$C$2:$C$109,$C37,'3_Curadoria'!$F$2:$F$109,"F") | J37: =COUNTIFS('3_Curadoria'!$C$2:$C$109,$C37,'3_Curadoria'!$F$2:$F$109,"P") | K37: =SUM(D37:J37)
C38: Aminoácido | D38: =COUNTIFS('3_Curadoria'!$C$2:$C$109,$C38,'3_Curadoria'!$F$2:$F$109,"A") | E38: =COUNTIFS('3_Curadoria'!$C$2:$C$109,$C38,'3_Curadoria'!$F$2:$F$109,"B") | F38: =COUNTIFS('3_Curadoria'!$C$2:$C$109,$C38,'3_Curadoria'!$F$2:$F$109,"C") | G38: =COUNTIFS('3_Curadoria'!$C$2:$C$109,$C38,'3_Curadoria'!$F$2:$F$109,"D") | H38: =COUNTIFS('3_Curadoria'!$C$2:$C$109,$C38,'3_Curadoria'!$F$2:$F$109,"E") | I38: =COUNTIFS('3_Curadoria'!$C$2:$C$109,$C38,'3_Curadoria'!$F$2:$F$109,"F") | J38: =COUNTIFS('3_Curadoria'!$C$2:$C$109,$C38,'3_Curadoria'!$F$2:$F$109,"P") | K38: =SUM(D38:J38)
... C95: β-carbolina | D95: =COUNTIFS('3_Curadoria'!$C$2:$C$109,$C95,'3_Curadoria'!$F$2:$F$109,"A") | E95: =COUNTIFS('3_Curadoria'!$C$2:$C$109,$C95,'3_Curadoria'!$F$2:$F$109,"B") | F95: =COUNTIFS('3_Curadoria'!$C$2:$C$109,$C95,'3_Curadoria'!$F$2:$F$109,"C") | G95: =COUNTIFS('3_Curadoria'!$C$2:$C$109,$C95,'3_Curadoria'!$F$2:$F$109,"D") | H95: =COUNTIFS('3_Curadoria'!$C$2:$C$109,$C95,'3_Curadoria'!$F$2:$F$109,"E") | I95: =COUNTIFS('3_Curadoria'!$C$2:$C$109,$C95,'3_Curadoria'!$F$2:$F$109,"F") | J95: =COUNTIFS('3_Curadoria'!$C$2:$C$109,$C95,'3_Curadoria'!$F$2:$F$109,"P") | K95: =SUM(D95:J95)

Sheet 1_Bruto
A1: Número | B1: Componente (original)
A2: 1 | B2: (1)-1,2,3,4-Tetrahydroisoquinoline-3-carboxylic acid CollisionEnergy:205060
A3: 2 | B3: 1-(2H-benzo[3,4-d]1,3-dioxolen-5-yl)-5-[(4-piperidylphenyl)methylene]-1,3-dihy dropyrimidine-2,4,6-trione CollisionEnergy:102040
A4: 3 | B4: 1-(2-Hydroxyethyl)-2,2,6,6-tetramethyl-4-piperidinol
A5: 4 | B5: 1,7-bis(4-hydroxyphenyl)-5-[(2R,3R,4S,5S,6R)-3,4,5-trihydroxy-6-(hydroxymethyl)oxan-2-yl]oxyheptan-3-one
A6: 5 | B6: (1R,3r,8S,9r)-1,8-dimethyl-3,6-diazatricyclo[4.3.1.1(3,8)]undecan-9-ol
A7: 6 | B7: [(1S,9S,13R,14R)-14-hydroxy-14-(hydroxymethyl)-5,5-dimethyltetracyclo[11.2.1.0¹,¹?.0?,?]hexadecan-9-yl]methyl (2E)-3-(3,4-dihydroxyphenyl)prop-2-enoate
A8: 7 | B8: 2,2'-Dihydroxychalcone CollisionEnergy:102040
A9: 8 | B9: 2',5-Dimethoxyflavone CollisionEnergy:102040
A10: 9 | B10: 2-Hydroxy-4,6-dimethoxyacetophenone
A11: 10 | B11: 3.10S-Hydroxypheophorbide a
A12: 11 | B12: 3,4,5-Trimethoxyphenol CollisionEnergy:102040
A13: 12 | B13: 3,4,5-Trimethoxyphenol CollisionEnergy:205060
... A149: 148 | B149: THYMINE - 30.0 eV

Sheet 2_Limpo
A1: Nº original | B1: Nome original | C1: Composto padronizado | D1: Biblioteca | E1: ID no banco | F1: Energia de colisão | G1: Problemas de qualidade encontrados | H1: Nº de linhas do mesmo composto | I1: Duplicata? | J1: Categoria (A–F) | K1: Ação recomendada
A2: 1 | B2: (1)-1,2,3,4-Tetrahydroisoquinoline-3-carboxylic acid CollisionEnergy:205060 | C2: 1,2,3,4-Tetrahydroisoquinoline-3-carboxylic acid (Tic) | D2: Não informada | F2: 20/50/60 (escalonada) | G2: energia de colisão embutida no nome | H2: =COUNTIF($C$2:$C$149,C2) | I2: =IF(COUNTIF($C$2:C2,C2)>1,"Sim","Não") | J2: =INDEX('3_Curadoria'!$F$2:$F$109,MATCH(C2,'3_Curadoria'!$B$2:$B$109,0)) | K2: =INDEX('3_Curadoria'!$H$2:$H$109,MATCH(C2,'3_Curadoria'!$B$2:$B$109,0))
A3: 2 | B3: 1-(2H-benzo[3,4-d]1,3-dioxolen-5-yl)-5-[(4-piperidylphenyl)methylene]-1,3-dihy dropyrimidine-2,4,6-trione CollisionEnergy:102040 | C3: Pyrimidinetrione (barbiturate) derivative | D3: Não informada | F3: 10/20/40 (escalonada) | G3: energia de colisão embutida no nome; espaço indevido dentro do nome | H3: =COUNTIF($C$2:$C$149,C3) | I3: =IF(COUNTIF($C$2:C3,C3)>1,"Sim","Não") | J3: =INDEX('3_Curadoria'!$F$2:$F$109,MATCH(C3,'3_Curadoria'!$B$2:$B$109,0)) | K3: =INDEX('3_Curadoria'!$H$2:$H$109,MATCH(C3,'3_Curadoria'!$B$2:$B$109,0))
A4: 3 | B4: 1-(2-Hydroxyethyl)-2,2,6,6-tetramethyl-4-piperidinol | C4: 1-(2-Hydroxyethyl)-2,2,6,6-tetramethyl-4-piperidinol | D4: Não informada | F4: Não informada | G4: — | H4: =COUNTIF($C$2:$C$149,C4) | I4: =IF(COUNTIF($C$2:C4,C4)>1,"Sim","Não") | J4: =INDEX('3_Curadoria'!$F$2:$F$109,MATCH(C4,'3_Curadoria'!$B$2:$B$109,0)) | K4: =INDEX('3_Curadoria'!$H$2:$H$109,MATCH(C4,'3_Curadoria'!$B$2:$B$109,0))
A5: 4 | B5: 1,7-bis(4-hydroxyphenyl)-5-[(2R,3R,4S,5S,6R)-3,4,5-trihydroxy-6-(hydroxymethyl)oxan-2-yl]oxyheptan-3-one | C5: Diarylheptanoid glucoside (1,7-bis(4-hydroxyphenyl)heptan-3-one 5-O-glucoside) | D5: Não informada | F5: Não informada | G5: — | H5: =COUNTIF($C$2:$C$149,C5) | I5: =IF(COUNTIF($C$2:C5,C5)>1,"Sim","Não") | J5: =INDEX('3_Curadoria'!$F$2:$F$109,MATCH(C5,'3_Curadoria'!$B$2:$B$109,0)) | K5: =INDEX('3_Curadoria'!$H$2:$H$109,MATCH(C5,'3_Curadoria'!$B$2:$B$109,0))
A6: 5 | B6: (1R,3r,8S,9r)-1,8-dimethyl-3,6-diazatricyclo[4.3.1.1(3,8)]undecan-9-ol | C6: 1,8-Dimethyl-3,6-diazatricyclo[4.3.1.1(3,8)]undecan-9-ol | D6: Não informada | F6: Não informada | G6: — | H6: =COUNTIF($C$2:$C$149,C6) | I6: =IF(COUNTIF($C$2:C6,C6)>1,"Sim","Não") | J6: =INDEX('3_Curadoria'!$F$2:$F$109,MATCH(C6,'3_Curadoria'!$B$2:$B$109,0)) | K6: =INDEX('3_Curadoria'!$H$2:$H$109,MATCH(C6,'3_Curadoria'!$B$2:$B$109,0))
A7: 6 | B7: [(1S,9S,13R,14R)-14-hydroxy-14-(hydroxymethyl)-5,5-dimethyltetracyclo[11.2.1.0¹,¹?.0?,?]hexadecan-9-yl]methyl (2E)-3-(3,4-dihydroxyphenyl)prop-2-enoate | C7: Kaurane-type diterpenoid caffeate ester | D7: Não informada | F7: Não informada | G7: caractere corrompido (encoding) | H7: =COUNTIF($C$2:$C$149,C7) | I7: =IF(COUNTIF($C$2:C7,C7)>1,"Sim","Não") | J7: =INDEX('3_Curadoria'!$F$2:$F$109,MATCH(C7,'3_Curadoria'!$B$2:$B$109,0)) | K7: =INDEX('3_Curadoria'!$H$2:$H$109,MATCH(C7,'3_Curadoria'!$B$2:$B$109,0))
A8: 7 | B8: 2,2'-Dihydroxychalcone CollisionEnergy:102040 | C8: 2,2'-Dihydroxychalcone | D8: Não informada | F8: 10/20/40 (escalonada) | G8: energia de colisão embutida no nome | H8: =COUNTIF($C$2:$C$149,C8) | I8: =IF(COUNTIF($C$2:C8,C8)>1,"Sim","Não") | J8: =INDEX('3_Curadoria'!$F$2:$F$109,MATCH(C8,'3_Curadoria'!$B$2:$B$109,0)) | K8: =INDEX('3_Curadoria'!$H$2:$H$109,MATCH(C8,'3_Curadoria'!$B$2:$B$109,0))
A9: 8 | B9: 2',5-Dimethoxyflavone CollisionEnergy:102040 | C9: 2',5-Dimethoxyflavone | D9: Não informada | F9: 10/20/40 (escalonada) | G9: energia de colisão embutida no nome | H9: =COUNTIF($C$2:$C$149,C9) | I9: =IF(COUNTIF($C$2:C9,C9)>1,"Sim","Não") | J9: =INDEX('3_Curadoria'!$F$2:$F$109,MATCH(C9,'3_Curadoria'!$B$2:$B$109,0)) | K9: =INDEX('3_Curadoria'!$H$2:$H$109,MATCH(C9,'3_Curadoria'!$B$2:$B$109,0))
A10: 9 | B10: 2-Hydroxy-4,6-dimethoxyacetophenone | C10: 2-Hydroxy-4,6-dimethoxyacetophenone (xanthoxylin) | D10: Não informada | F10: Não informada | G10: — | H10: =COUNTIF($C$2:$C$149,C10) | I10: =IF(COUNTIF($C$2:C10,C10)>1,"Sim","Não") | J10: =INDEX('3_Curadoria'!$F$2:$F$109,MATCH(C10,'3_Curadoria'!$B$2:$B$109,0)) | K10: =INDEX('3_Curadoria'!$H$2:$H$109,MATCH(C10,'3_Curadoria'!$B$2:$B$109,0))
A11: 10 | B11: 3.10S-Hydroxypheophorbide a | C11: 13²-Hydroxypheophorbide a | D11: Não informada | F11: Não informada | G11: nomenclatura irregular | H11: =COUNTIF($C$2:$C$149,C11) | I11: =IF(COUNTIF($C$2:C11,C11)>1,"Sim","Não") | J11: =INDEX('3_Curadoria'!$F$2:$F$109,MATCH(C11,'3_Curadoria'!$B$2:$B$109,0)) | K11: =INDEX('3_Curadoria'!$H$2:$H$109,MATCH(C11,'3_Curadoria'!$B$2:$B$109,0))
A12: 11 | B12: 3,4,5-Trimethoxyphenol CollisionEnergy:102040 | C12: 3,4,5-Trimethoxyphenol | D12: Não informada | F12: 10/20/40 (escalonada) | G12: energia de colisão embutida no nome | H12: =COUNTIF($C$2:$C$149,C12) | I12: =IF(COUNTIF($C$2:C12,C12)>1,"Sim","Não") | J12: =INDEX('3_Curadoria'!$F$2:$F$109,MATCH(C12,'3_Curadoria'!$B$2:$B$109,0)) | K12: =INDEX('3_Curadoria'!$H$2:$H$109,MATCH(C12,'3_Curadoria'!$B$2:$B$109,0))
A13: 12 | B13: 3,4,5-Trimethoxyphenol CollisionEnergy:205060 | C13: 3,4,5-Trimethoxyphenol | D13: Não informada | F13: 20/50/60 (escalonada) | G13: energia de colisão embutida no nome | H13: =COUNTIF($C$2:$C$149,C13) | I13: =IF(COUNTIF($C$2:C13,C13)>1,"Sim","Não") | J13: =INDEX('3_Curadoria'!$F$2:$F$109,MATCH(C13,'3_Curadoria'!$B$2:$B$109,0)) | K13: =INDEX('3_Curadoria'!$H$2:$H$109,MATCH(C13,'3_Curadoria'!$B$2:$B$109,0))
... A53: 52 | B53: Harmane | C53: Harmane | D53: Não informada | F53: Não informada | G53: — | H53: =COUNTIF($C$2:$C$149,C53) | I53: =IF(COUNTIF($C$2:C53,C53)>1,"Sim","Não") | J53: =INDEX('3_Curadoria'!$F$2:$F$109,MATCH(C53,'3_Curadoria'!$B$2:$B$109,0)) | K53: =INDEX('3_Curadoria'!$H$2:$H$109,MATCH(C53,'3_Curadoria'!$B$2:$B$109,0))
A54: 53 | B54: HMDB:HMDB02001-1936 Dimethylmalonic acid | C54: Dimethylmalonic acid | D54: HMDB | E54: HMDB02001-1936 | F54: Não informada | G54: ID do banco embutido no nome | H54: =COUNTIF($C$2:$C$149,C54) | I54: =IF(COUNTIF($C$2:C54,C54)>1,"Sim","Não") | J54: =INDEX('3_Curadoria'!$F$2:$F$109,MATCH(C54,'3_Curadoria'!$B$2:$B$109,0)) | K54: =INDEX('3_Curadoria'!$H$2:$H$109,MATCH(C54,'3_Curadoria'!$B$2:$B$109,0))
A55: 54 | B55: HYPOXANTHINE | C55: Hypoxanthine | D55: Não informada | F55: Não informada | G55: caixa alta inconsistente | H55: =COUNTIF($C$2:$C$149,C55) | I55: =IF(COUNTIF($C$2:C55,C55)>1,"Sim","Não") | J55: =INDEX('3_Curadoria'!$F$2:$F$109,MATCH(C55,'3_Curadoria'!$B$2:$B$109,0)) | K55: =INDEX('3_Curadoria'!$H$2:$H$109,MATCH(C55,'3_Curadoria'!$B$2:$B$109,0))
A56: 55 | B56: INDOLEACETIC ACID | C56: Indole-3-acetic acid | D56: Não informada | F56: Não informada | G56: caixa alta inconsistente | H56: =COUNTIF($C$2:$C$149,C56) | I56: =IF(COUNTIF($C$2:C56,C56)>1,"Sim","Não") | J56: =INDEX('3_Curadoria'!$F$2:$F$109,MATCH(C56,'3_Curadoria'!$B$2:$B$109,0)) | K56: =INDEX('3_Curadoria'!$H$2:$H$109,MATCH(C56,'3_Curadoria'!$B$2:$B$109,0))
A57: 56 | B57: INDOLEACRYLIC ACID | C57: 3-Indoleacrylic acid | D57: Não informada | F57: Não informada | G57: caixa alta inconsistente | H57: =COUNTIF($C$2:$C$149,C57) | I57: =IF(COUNTIF($C$2:C57,C57)>1,"Sim","Não") | J57: =INDEX('3_Curadoria'!$F$2:$F$109,MATCH(C57,'3_Curadoria'!$B$2:$B$109,0)) | K57: =INDEX('3_Curadoria'!$H$2:$H$109,MATCH(C57,'3_Curadoria'!$B$2:$B$109,0))
A58: 57 | B58: ISOLEUCINE | C58: Isoleucine | D58: Não informada | F58: Não informada | G58: caixa alta inconsistente | H58: =COUNTIF($C$2:$C$149,C58) | I58: =IF(COUNTIF($C$2:C58,C58)>1,"Sim","Não") | J58: =INDEX('3_Curadoria'!$F$2:$F$109,MATCH(C58,'3_Curadoria'!$B$2:$B$109,0)) | K58: =INDEX('3_Curadoria'!$H$2:$H$109,MATCH(C58,'3_Curadoria'!$B$2:$B$109,0))
A59: 58 | B59: ISOLEUCINE - 20.0 eV | C59: Isoleucine | D59: Não informada | F59: 20 eV | G59: energia de colisão embutida no nome; caixa alta inconsistente | H59: =COUNTIF($C$2:$C$149,C59) | I59: =IF(COUNTIF($C$2:C59,C59)>1,"Sim","Não") | J59: =INDEX('3_Curadoria'!$F$2:$F$109,MATCH(C59,'3_Curadoria'!$B$2:$B$109,0)) | K59: =INDEX('3_Curadoria'!$H$2:$H$109,MATCH(C59,'3_Curadoria'!$B$2:$B$109,0))
A60: 59 | B60: ISOLEUCINE - 30.0 eV | C60: Isoleucine | D60: Não informada | F60: 30 eV | G60: energia de colisão embutida no nome; caixa alta inconsistente | H60: =COUNTIF($C$2:$C$149,C60) | I60: =IF(COUNTIF($C$2:C60,C60)>1,"Sim","Não") | J60: =INDEX('3_Curadoria'!$F$2:$F$109,MATCH(C60,'3_Curadoria'!$B$2:$B$109,0)) | K60: =INDEX('3_Curadoria'!$H$2:$H$109,MATCH(C60,'3_Curadoria'!$B$2:$B$109,0))
A61: 60 | B61: Isovaleric acid | C61: Isovaleric acid | D61: Não informada | F61: Não informada | G61: — | H61: =COUNTIF($C$2:$C$149,C61) | I61: =IF(COUNTIF($C$2:C61,C61)>1,"Sim","Não") | J61: =INDEX('3_Curadoria'!$F$2:$F$109,MATCH(C61,'3_Curadoria'!$B$2:$B$109,0)) | K61: =INDEX('3_Curadoria'!$H$2:$H$109,MATCH(C61,'3_Curadoria'!$B$2:$B$109,0))
A62: 61 | B62: jasmonic acid methyl ester CollisionEnergy:205060 | C62: Methyl jasmonate | D62: Não informada | F62: 20/50/60 (escalonada) | G62: energia de colisão embutida no nome | H62: =COUNTIF($C$2:$C$149,C62) | I62: =IF(COUNTIF($C$2:C62,C62)>1,"Sim","Não") | J62: =INDEX('3_Curadoria'!$F$2:$F$109,MATCH(C62,'3_Curadoria'!$B$2:$B$109,0)) | K62: =INDEX('3_Curadoria'!$H$2:$H$109,MATCH(C62,'3_Curadoria'!$B$2:$B$109,0))
A63: 62 | B63: kynurenic acid CollisionEnergy:205060 | C63: Kynurenic acid | D63: Não informada | F63: 20/50/60 (escalonada) | G63: energia de colisão embutida no nome | H63: =COUNTIF($C$2:$C$149,C63) | I63: =IF(COUNTIF($C$2:C63,C63)>1,"Sim","Não") | J63: =INDEX('3_Curadoria'!$F$2:$F$109,MATCH(C63,'3_Curadoria'!$B$2:$B$109,0)) | K63: =INDEX('3_Curadoria'!$H$2:$H$109,MATCH(C63,'3_Curadoria'!$B$2:$B$109,0))
A64: 63 | B64: LEUCINE | C64: Leucine | D64: Não informada | F64: Não informada | G64: caixa alta inconsistente | H64: =COUNTIF($C$2:$C$149,C64) | I64: =IF(COUNTIF($C$2:C64,C64)>1,"Sim","Não") | J64: =INDEX('3_Curadoria'!$F$2:$F$109,MATCH(C64,'3_Curadoria'!$B$2:$B$109,0)) | K64: =INDEX('3_Curadoria'!$H$2:$H$109,MATCH(C64,'3_Curadoria'!$B$2:$B$109,0))
A65: 64 | B65: Leucine - 20.00 eV | C65: Leucine | D65: Não informada | F65: 20 eV | G65: energia de colisão embutida no nome | H65: =COUNTIF($C$2:$C$149,C65) | I65: =IF(COUNTIF($C$2:C65,C65)>1,"Sim","Não") | J65: =INDEX('3_Curadoria'!$F$2:$F$109,MATCH(C65,'3_Curadoria'!$B$2:$B$109,0)) | K65: =INDEX('3_Curadoria'!$H$2:$H$109,MATCH(C65,'3_Curadoria'!$B$2:$B$109,0))
A66: 65 | B66: LEUCINE - 20.00 eV | C66: Leucine | D66: Não informada | F66: 20 eV | G66: energia de colisão embutida no nome; caixa alta inconsistente | H66: =COUNTIF($C$2:$C$149,C66) | I66: =IF(COUNTIF($C$2:C66,C66)>1,"Sim","Não") | J66: =INDEX('3_Curadoria'!$F$2:$F$109,MATCH(C66,'3_Curadoria'!$B$2:$B$109,0)) | K66: =INDEX('3_Curadoria'!$H$2:$H$109,MATCH(C66,'3_Curadoria'!$B$2:$B$109,0))
... A76: 75 | B76: MANNOSE | C76: Mannose | D76: Não informada | F76: Não informada | G76: caixa alta inconsistente | H76: =COUNTIF($C$2:$C$149,C76) | I76: =IF(COUNTIF($C$2:C76,C76)>1,"Sim","Não") | J76: =INDEX('3_Curadoria'!$F$2:$F$109,MATCH(C76,'3_Curadoria'!$B$2:$B$109,0)) | K76: =INDEX('3_Curadoria'!$H$2:$H$109,MATCH(C76,'3_Curadoria'!$B$2:$B$109,0))
A77: 76 | B77: Massbank:AU252106 4-Hydroxy-1-(2-hydroxyethyl)-2,2,6,6-tetramethylpiperidine|1-Piperidineethanol, 4-hydroxy-2,2,6,6-tetramethyl-|1-(2-hydroxyethyl)-2,2,6,6-tetramethylpiperidin-4-ol | C77: 1-(2-Hydroxyethyl)-2,2,6,6-tetramethyl-4-piperidinol | D77: MassBank | E77: AU252106 | F77: Não informada | G77: ID do banco embutido no nome; sinônimos concatenados com '|' | H77: =COUNTIF($C$2:$C$149,C77) | I77: =IF(COUNTIF($C$2:C77,C77)>1,"Sim","Não") | J77: =INDEX('3_Curadoria'!$F$2:$F$109,MATCH(C77,'3_Curadoria'!$B$2:$B$109,0)) | K77: =INDEX('3_Curadoria'!$H$2:$H$109,MATCH(C77,'3_Curadoria'!$B$2:$B$109,0))
A78: 77 | B78: Massbank:EA021311 DEET|N,N-Diethyl-m-toluamide|N,N-diethyl-3-methyl-benzamide | C78: DEET | D78: MassBank | E78: EA021311 | F78: Não informada | G78: ID do banco embutido no nome; sinônimos concatenados com '|' | H78: =COUNTIF($C$2:$C$149,C78) | I78: =IF(COUNTIF($C$2:C78,C78)>1,"Sim","Não") | J78: =INDEX('3_Curadoria'!$F$2:$F$109,MATCH(C78,'3_Curadoria'!$B$2:$B$109,0)) | K78: =INDEX('3_Curadoria'!$H$2:$H$109,MATCH(C78,'3_Curadoria'!$B$2:$B$109,0))
A79: 78 | B79: Massbank:EQ309203 Diphenylamine|N-phenylaniline | C79: Diphenylamine | D79: MassBank | E79: EQ309203 | F79: Não informada | G79: ID do banco embutido no nome; sinônimos concatenados com '|' | H79: =COUNTIF($C$2:$C$149,C79) | I79: =IF(COUNTIF($C$2:C79,C79)>1,"Sim","Não") | J79: =INDEX('3_Curadoria'!$F$2:$F$109,MATCH(C79,'3_Curadoria'!$B$2:$B$109,0)) | K79: =INDEX('3_Curadoria'!$H$2:$H$109,MATCH(C79,'3_Curadoria'!$B$2:$B$109,0))
A80: 79 | B80: Massbank:EQ309204 Diphenylamine|N-phenylaniline | C80: Diphenylamine | D80: MassBank | E80: EQ309204 | F80: Não informada | G80: ID do banco embutido no nome; sinônimos concatenados com '|' | H80: =COUNTIF($C$2:$C$149,C80) | I80: =IF(COUNTIF($C$2:C80,C80)>1,"Sim","Não") | J80: =INDEX('3_Curadoria'!$F$2:$F$109,MATCH(C80,'3_Curadoria'!$B$2:$B$109,0)) | K80: =INDEX('3_Curadoria'!$H$2:$H$109,MATCH(C80,'3_Curadoria'!$B$2:$B$109,0))
A81: 80 | B81: Massbank:LU129801 4-Chlorophenylurea|(4-chlorophenyl)urea | C81: 4-Chlorophenylurea | D81: MassBank | E81: LU129801 | F81: Não informada | G81: ID do banco embutido no nome; sinônimos concatenados com '|' | H81: =COUNTIF($C$2:$C$149,C81) | I81: =IF(COUNTIF($C$2:C81,C81)>1,"Sim","Não") | J81: =INDEX('3_Curadoria'!$F$2:$F$109,MATCH(C81,'3_Curadoria'!$B$2:$B$109,0)) | K81: =INDEX('3_Curadoria'!$H$2:$H$109,MATCH(C81,'3_Curadoria'!$B$2:$B$109,0))
A82: 81 | B82: Massbank:PB000393 Leucine|2-amino-4-methylpentanoic acid | C82: Leucine | D82: MassBank | E82: PB000393 | F82: Não informada | G82: ID do banco embutido no nome; sinônimos concatenados com '|' | H82: =COUNTIF($C$2:$C$149,C82) | I82: =IF(COUNTIF($C$2:C82,C82)>1,"Sim","Não") | J82: =INDEX('3_Curadoria'!$F$2:$F$109,MATCH(C82,'3_Curadoria'!$B$2:$B$109,0)) | K82: =INDEX('3_Curadoria'!$H$2:$H$109,MATCH(C82,'3_Curadoria'!$B$2:$B$109,0))
A83: 82 | B83: Massbank:PB000397 Isoleucine|2-amino-3-methylpentanoic acid | C83: Isoleucine | D83: MassBank | E83: PB000397 | F83: Não informada | G83: ID do banco embutido no nome; sinônimos concatenados com '|' | H83: =COUNTIF($C$2:$C$149,C83) | I83: =IF(COUNTIF($C$2:C83,C83)>1,"Sim","Não") | J83: =INDEX('3_Curadoria'!$F$2:$F$109,MATCH(C83,'3_Curadoria'!$B$2:$B$109,0)) | K83: =INDEX('3_Curadoria'!$H$2:$H$109,MATCH(C83,'3_Curadoria'!$B$2:$B$109,0))
A84: 83 | B84: Massbank:PB000408 Phenylalanine|2-amino-3-phenylpropanoic acid | C84: Phenylalanine | D84: MassBank | E84: PB000408 | F84: Não informada | G84: ID do banco embutido no nome; sinônimos concatenados com '|' | H84: =COUNTIF($C$2:$C$149,C84) | I84: =IF(COUNTIF($C$2:C84,C84)>1,"Sim","Não") | J84: =INDEX('3_Curadoria'!$F$2:$F$109,MATCH(C84,'3_Curadoria'!$B$2:$B$109,0)) | K84: =INDEX('3_Curadoria'!$H$2:$H$109,MATCH(C84,'3_Curadoria'!$B$2:$B$109,0))
A85: 84 | B85: Massbank:PB000458 Asparagine|2,4-diamino-4-oxobutanoic acid | C85: Asparagine | D85: MassBank | E85: PB000458 | F85: Não informada | G85: ID do banco embutido no nome; sinônimos concatenados com '|' | H85: =COUNTIF($C$2:$C$149,C85) | I85: =IF(COUNTIF($C$2:C85,C85)>1,"Sim","Não") | J85: =INDEX('3_Curadoria'!$F$2:$F$109,MATCH(C85,'3_Curadoria'!$B$2:$B$109,0)) | K85: =INDEX('3_Curadoria'!$H$2:$H$109,MATCH(C85,'3_Curadoria'!$B$2:$B$109,0))
A86: 85 | B86: Massbank:PB000619 Syringaldehyde|4-hydroxy-3,5-dimethoxybenzaldehyde | C86: Syringaldehyde | D86: MassBank | E86: PB000619 | F86: Não informada | G86: ID do banco embutido no nome; sinônimos concatenados com '|' | H86: =COUNTIF($C$2:$C$149,C86) | I86: =IF(COUNTIF($C$2:C86,C86)>1,"Sim","Não") | J86: =INDEX('3_Curadoria'!$F$2:$F$109,MATCH(C86,'3_Curadoria'!$B$2:$B$109,0)) | K86: =INDEX('3_Curadoria'!$H$2:$H$109,MATCH(C86,'3_Curadoria'!$B$2:$B$109,0))
A87: 86 | B87: Massbank:RP030402 ?-linolenic acid|linolenic acid|(9Z,12Z,15Z)-octadeca-9,12,15-trienoic acid | C87: alpha-Linolenic acid | D87: MassBank | E87: RP030402 | F87: Não informada | G87: ID do banco embutido no nome; sinônimos concatenados com '|'; caractere corrompido (encoding) | H87: =COUNTIF($C$2:$C$149,C87) | I87: =IF(COUNTIF($C$2:C87,C87)>1,"Sim","Não") | J87: =INDEX('3_Curadoria'!$F$2:$F$109,MATCH(C87,'3_Curadoria'!$B$2:$B$109,0)) | K87: =INDEX('3_Curadoria'!$H$2:$H$109,MATCH(C87,'3_Curadoria'!$B$2:$B$109,0))
A88: 87 | B88: Massbank:RP030403 ?-linolenic acid|linolenic acid|(9Z,12Z,15Z)-octadeca-9,12,15-trienoic acid | C88: alpha-Linolenic acid | D88: MassBank | E88: RP030403 | F88: Não informada | G88: ID do banco embutido no nome; sinônimos concatenados com '|'; caractere corrompido (encoding) | H88: =COUNTIF($C$2:$C$149,C88) | I88: =IF(COUNTIF($C$2:C88,C88)>1,"Sim","Não") | J88: =INDEX('3_Curadoria'!$F$2:$F$109,MATCH(C88,'3_Curadoria'!$B$2:$B$109,0)) | K88: =INDEX('3_Curadoria'!$H$2:$H$109,MATCH(C88,'3_Curadoria'!$B$2:$B$109,0))
...

Sheet 3_Curadoria
A1: ID | B1: Composto padronizado | C1: Classe química | D1: Nº de linhas na lista | E1: Linhas originais | F1: Categoria (A–F) | G1: Plausibilidade | H1: Ação recomendada | I1: Grupo isomérico / ressalva de anotação | J1: Nível MSI sugerido | K1: Justificativa | L1: Referências
A2: 1 | B2: Choline | C2: Amina quaternária | D2: =COUNTIF('2_Limpo'!$C$2:$C$149,B2) | E2: 34, 123 | F2: A | G2: =INDEX('4_Resumo'!$C$5:$C$11,MATCH(F2,'4_Resumo'!$B$5:$B$11,0)) | H2: =INDEX('4_Resumo'!$D$5:$D$11,MATCH(F2,'4_Resumo'!$B$5:$B$11,0)) | I2: — | J2: 2 | K2: Relatada em V. planifolia. | L2: R1
A3: 2 | B3: Asparagine | C3: Aminoácido | D3: =COUNTIF('2_Limpo'!$C$2:$C$149,B3) | E3: 30, 84 | F3: A | G3: =INDEX('4_Resumo'!$C$5:$C$11,MATCH(F3,'4_Resumo'!$B$5:$B$11,0)) | H3: =INDEX('4_Resumo'!$D$5:$D$11,MATCH(F3,'4_Resumo'!$B$5:$B$11,0)) | I3: — | J3: 2 | K3: Relatada em V. planifolia. | L3: R1
A4: 3 | B4: Isoleucine | C4: Aminoácido | D4: =COUNTIF('2_Limpo'!$C$2:$C$149,B4) | E4: 57, 58, 59, 70, 82 | F4: A | G4: =INDEX('4_Resumo'!$C$5:$C$11,MATCH(F4,'4_Resumo'!$B$5:$B$11,0)) | H4: =INDEX('4_Resumo'!$D$5:$D$11,MATCH(F4,'4_Resumo'!$B$5:$B$11,0)) | I4: C6H13NO2 (Leu/Ile/allo-Ile/Nle) — indistinguíveis por MS/MS | J4: 3 | K4: Isoleucina relatada em V. planifolia. Isômero de Leu — consolidar como 'Leu/Ile'. | L4: R1
A5: 4 | B5: Leucine | C5: Aminoácido | D5: =COUNTIF('2_Limpo'!$C$2:$C$149,B5) | E5: 63, 64, 65, 66, 67, 68, 71, 81 | F5: A | G5: =INDEX('4_Resumo'!$C$5:$C$11,MATCH(F5,'4_Resumo'!$B$5:$B$11,0)) | H5: =INDEX('4_Resumo'!$D$5:$D$11,MATCH(F5,'4_Resumo'!$B$5:$B$11,0)) | I5: C6H13NO2 (Leu/Ile/allo-Ile/Nle) — indistinguíveis por MS/MS | J5: 3 | K5: Leucina relatada em folhas/caules/raízes de V. planifolia. Reportar a feature como 'Leu/Ile'. | L5: R1
A6: 5 | B6: Phenylalanine | C6: Aminoácido | D6: =COUNTIF('2_Limpo'!$C$2:$C$149,B6) | E6: 83, 88 | F6: A | G6: =INDEX('4_Resumo'!$C$5:$C$11,MATCH(F6,'4_Resumo'!$B$5:$B$11,0)) | H6: =INDEX('4_Resumo'!$D$5:$D$11,MATCH(F6,'4_Resumo'!$B$5:$B$11,0)) | I6: — | J6: 2 | K6: Relatada em V. planifolia; precursora da rota fenilpropanoide/vanilina. | L6: R1; R7
A7: 6 | B7: Tyrosine | C7: Aminoácido | D7: =COUNTIF('2_Limpo'!$C$2:$C$149,B7) | E7: 89 | F7: A | G7: =INDEX('4_Resumo'!$C$5:$C$11,MATCH(F7,'4_Resumo'!$B$5:$B$11,0)) | H7: =INDEX('4_Resumo'!$D$5:$D$11,MATCH(F7,'4_Resumo'!$B$5:$B$11,0)) | I7: — | J7: 2 | K7: Relatada em V. planifolia. | L7: R1
A8: 7 | B8: Arabinose | C8: Açúcar (pentose) | D8: =COUNTIF('2_Limpo'!$C$2:$C$149,B8) | E8: 28 | F8: A | G8: =INDEX('4_Resumo'!$C$5:$C$11,MATCH(F8,'4_Resumo'!$B$5:$B$11,0)) | H8: =INDEX('4_Resumo'!$D$5:$D$11,MATCH(F8,'4_Resumo'!$B$5:$B$11,0)) | I8: — | J8: 2 | K8: Relatada em V. planifolia. | L8: R1
A9: 8 | B9: Guaiacol | C9: Fenol volátil | D9: =COUNTIF('2_Limpo'!$C$2:$C$149,B9) | E9: 48, 49 | F9: A | G9: =INDEX('4_Resumo'!$C$5:$C$11,MATCH(F9,'4_Resumo'!$B$5:$B$11,0)) | H9: =INDEX('4_Resumo'!$D$5:$D$11,MATCH(F9,'4_Resumo'!$B$5:$B$11,0)) | I9: — | J9: 2 | K9: Composto de aroma da baunilha curada. Por ser volátil, é atípico em LC-MS; confirmar. | L9: R5
A10: 9 | B10: Diosmin | C10: Flavonoide (flavona glicosilada) | D10: =COUNTIF('2_Limpo'!$C$2:$C$149,B10) | E10: 40 | F10: A | G10: =INDEX('4_Resumo'!$C$5:$C$11,MATCH(F10,'4_Resumo'!$B$5:$B$11,0)) | H10: =INDEX('4_Resumo'!$D$5:$D$11,MATCH(F10,'4_Resumo'!$B$5:$B$11,0)) | I10: — | J10: 2 | K10: Diosmetina e 'diosmetina desoxi-hexose-hexose' (= composição da diosmina) foram relatadas em V. planifolia. | L10: R1
A11: 10 | B11: D-Mannitol | C11: Poliol | D11: =COUNTIF('2_Limpo'!$C$2:$C$149,B11) | E11: 41 | F11: A | G11: =INDEX('4_Resumo'!$C$5:$C$11,MATCH(F11,'4_Resumo'!$B$5:$B$11,0)) | H11: =INDEX('4_Resumo'!$D$5:$D$11,MATCH(F11,'4_Resumo'!$B$5:$B$11,0)) | I11: — | J11: 2 | K11: Relatado em V. planifolia. | L11: R1
A12: 11 | B12: alpha-Linolenic acid | C12: Ácido graxo (18:3) | D12: =COUNTIF('2_Limpo'!$C$2:$C$149,B12) | E12: 86, 87 | F12: A | G12: =INDEX('4_Resumo'!$C$5:$C$11,MATCH(F12,'4_Resumo'!$B$5:$B$11,0)) | H12: =INDEX('4_Resumo'!$D$5:$D$11,MATCH(F12,'4_Resumo'!$B$5:$B$11,0)) | I12: — | J12: 2 | K12: Relatado em V. planifolia. O nome original estava com encoding quebrado ('?-linolenic'). | L12: R1
A13: 12 | B13: Ferulic acid | C13: Ácido hidroxicinâmico | D13: =COUNTIF('2_Limpo'!$C$2:$C$149,B13) | E13: 42, 141 | F13: A | G13: =INDEX('4_Resumo'!$C$5:$C$11,MATCH(F13,'4_Resumo'!$B$5:$B$11,0)) | H13: =INDEX('4_Resumo'!$D$5:$D$11,MATCH(F13,'4_Resumo'!$B$5:$B$11,0)) | I13: — | J13: 2 | K13: Relatado em V. planifolia; precursor direto da vanilina (VpVAN). | L13: R1; R4; R7
... A109: 108 | B109: 1,3-Dicyclohexylurea | C109: Ureia sintética | D109: =COUNTIF('2_Limpo'!$C$2:$C$149,B109) | E109: 111 | F109: F | G109: =INDEX('4_Resumo'!$C$5:$C$11,MATCH(F109,'4_Resumo'!$B$5:$B$11,0)) | H109: =INDEX('4_Resumo'!$D$5:$D$11,MATCH(F109,'4_Resumo'!$B$5:$B$11,0)) | I109: — | J109: 2 | K109: Subproduto do DCC (reagente de síntese) e contaminante conhecido de LC-MS. | L109: R8

Sheet 5_Referências
A1: Código | B1: Referência | C1: Link
A2: R1 | B2: Beer et al. (2025). Comprehensive metabolome characterization of leaves, internodes, and aerial roots of Vanilla planifolia by untargeted LC–MS and GC×GC–MS. Phytochemical Analysis. | C2: https://pmc.ncbi.nlm.nih.gov/articles/PMC11743222/
A3: R2 | B3: dos Santos et al. (2026). Chemical diversity and species differentiation in Brazilian Vanilla: insights from LC-HRMS/MS metabolomics. Metabolomics. | C3: https://link.springer.com/article/10.1007/s11306-026-02422-8
A4: R3 | B4: Vaz et al. (2022). LC-HRMS/MS-based metabolomics approaches applied to the detection of antifungal compounds and a metabolic dynamic assessment of Orchidaceae (Vanda e Cattleya). Molecules 27(22):7937. | C4: https://www.mdpi.com/1420-3049/27/22/7937
A5: R4 | B5: Hernández-Peña et al. (2025). Unravelling vanillin biosynthesis: integrative transcriptomic and metabolomic insights into pod development. J. Agric. Food Chem. | C5: https://pmc.ncbi.nlm.nih.gov/articles/PMC12314903/
A6: R5 | B6: Pérez-Silva et al. (2006). GC-MS and GC-olfactometry analysis of aroma compounds in a representative organic aroma extract from cured vanilla (V. planifolia) beans. Food Chemistry. | C6: https://www.researchgate.net/publication/223496777
A7: R6 | B7: Palama et al. (2009). Metabolic changes in different developmental stages of Vanilla planifolia pods. J. Agric. Food Chem. | C7: https://pubmed.ncbi.nlm.nih.gov/19681612/
A8: R7 | B8: Gallage et al. (2014). Vanillin formation from ferulic acid in Vanilla planifolia is catalysed by a single enzyme. Nature Communications. | C8: https://www.nature.com/articles/ncomms5037
A9: R8 | B9: Merck/Sigma-Aldrich. LC-MS Contaminants: avoid, identify, minimize (guia técnico). | C9: https://www.sigmaaldrich.com/deepweb/assets/sigmaaldrich/product/documents/210/830/lc-ms-contaminants-brochure-ms.pdf
A10: R9 | B10: Interference of oleamide with analytical and bioassay results (2020). Scientific Reports. | C10: https://www.nature.com/articles/s41598-020-59093-1
A11: R10 | B11: Bioactive β-Carbolines in Food: A Review (2019). Nutrients 11(4):814. | C11: https://www.mdpi.com/2072-6643/11/4/814
A12: R11 | B12: Thermally-induced formation of taste-active 2,5-diketopiperazines from short-chain peptide precursors in cocoa (2019). Food Research International. | C12: https://www.sciencedirect.com/science/article/abs/pii/S0963996919301590
A13: R12 | B13: Sumner et al. (2007). Proposed minimum reporting standards for chemical analysis (MSI). Metabolomics 3:211–221. | C13: https://doi.org/10.1007/s11306-007-0082-2
